Workbook

Sheet Proposal
A1: Project Report
A5: K D Tex Fab
A6: Sr No | B6: Particulars | C6: Amount in Lakhs
A7: 1 | B7: Machinery TL - 1 | C7: ='Machinery Chart'!F12/10^5 -> 251.59117
A8: 2 | B8: Machinery TL - 2 | C8: ='Machinery Chart'!F22/10^5 -> 158.23896
A9: 3 | B9: OD | C9: 75
B10: Total | C10: =SUM(C7:C9) -> 484.83013

Sheet Machinery Chart
A1: Phase 1 - 24 Waterjet Machines - List of Proposed Machinery
A2: Sr. No. | B2: Name of Supplier | C2: Description of machinery | D2: Nos | E2: Amount | F2: Total
A3: 1 | B3: Qingdao Huifang Textile Machinery Co., Ltd | C3: Waterjet | D3: 23 | E3: 269100 | F3: =E3*92 -> 24757200
A4: 2 | B4: Gateway Global Logistics LLP | F4: 5254456
A5: 3 | B5: Ananta Electricals | F5: 744289
A6: 4 | B6: SM Transformer | F6: 212400
A7: 5 | B7: Shital Envirotech Private Limited | F7: 1536360
A8: 6 | B8: Sadguru Enterprise | F8: 838980
A9: 7 | B9: Rajkot Hardware | F9: 201805
C11: Total | E11: =SUM(E3:E10) -> 269100 | F11: =SUM(F3:F10) -> 33545490
C12: Term Loan - 1 Proposed | E12: =F12/F11% -> 75 | F12: =F11*75% -> 25159118
C13: Customer Margin | E13: =F13/F11% -> 25 | F13: =F11-F12 -> 8386372.5
A14: Note | B14: Dollar Rate Considered for Conversion is Rs 92 per Dollar
A16: Phase 2 - 16 Waterjet Machines - List of Proposed Machinery
A17: Sr. No. | B17: Name of Supplier | C17: Description of machinery | D17: Nos | E17: Amount | F17: Total
A18: 1 | B18: Qingdao Huifang Textile Machinery Co., Ltd | C18: Waterjet | D18: 16 | E18: 187200 | F18: =E18*92 -> 17222400
A19: 2 | B19: Gateway Global Logistics LLP | F19: 3876128
C21: Total | E21: =SUM(E18:E20) -> 187200 | F21: =SUM(F18:F20) -> 21098528
C22: Term Loan - 1 Proposed | E22: =F22/F21% -> 75 | F22: =F21*75% -> 15823896
C23: Customer Margin | E23: =F23/F21% -> 25 | F23: =F21-F22 -> 5274632
A25: Note | B25: Dollar Rate Considered for Conversion is Rs 92 per Dollar

Sheet COP - MOF
A1: Cost of Project | D1: Means of Finance
A2: Sr No | B2: Particulars | C2: Amount in lakhs | D2: Sr No | E2: Particulars | F2: Amount in lakhs
A3: 1 | B3: Plant & Machinery | C3: =(+'Machinery Chart'!F11+'Machinery Chart'!F21)/10^5 -> 546.44018 | D3: 1 | E3: Term Loan 1 | F3: =+Proposal!C7 -> 251.59117
A4: 2 | B4: Working Capital | C4: =F9-C3 -> 113.38995 | D4: 2 | E4: Term Loan 2 | F4: =+Proposal!C8 -> 158.23896
D5: 3 | E5: Partner's Capital | F5: 150
D6: 4 | E6: Quasi Capital in form of USL | F6: 25
D7: 5 | E7: Working Capital - OD | F7: 75
C9: =SUM(C3:C8) -> 659.83013 | F9: =SUM(F3:F8) -> 659.83013

Sheet P&L
A1: PROFITABILITY STATEMENT
A2: DESCRIPTION | B2: 2027 | C2: 2028 | D2: 2029 | E2: 2030 | F2: 2031 | G2: 2032 | H2: 2033 | I2: 2034
B3: Projected | C3: Projected | D3: Projected | E3: Projected | F3: Projected | G3: Projected | H3: Projected | I3: Projected
A4: Operating Income
A5: Export sales – Direct
A6: Export sales – Deemed
A7: Domestic Sales (including credit card sales) - Jobwork Income | B7: ='Production Chart'!B25 -> 565.292 | C7: ='Production Chart'!C25 -> 1076.1319 | D7: ='Production Chart'!D25 -> 1160.9325 | E7: ='Production Chart'!E25 -> 1195.5694 | F7: ='Production Chart'!F25 -> 1230.684 | G7: ='Production Chart'!G25 -> 1266.2764 | H7: ='Production Chart'!H25 -> 1302.3465 | I7: ='Production Chart'!I25 -> 1338.8944
A8: - Credit card sales (as a part of domestic sales)
A9: Total Sales | B9: =SUM(B5:B8) -> 565.292 | C9: =SUM(C5:C8) -> 1076.1319 | D9: =SUM(D5:D8) -> 1160.9325 | E9: =SUM(E5:E8) -> 1195.5694 | F9: =SUM(F5:F8) -> 1230.684 | G9: =SUM(G5:G8) -> 1266.2764 | H9: =SUM(H5:H8) -> 1302.3465 | I9: =SUM(I5:I8) -> 1338.8944
A10: Non-Operating Income
A11: Other Income
A12: Interest and dividend
A13: Total | C13: =C11+C12 -> 0 | D13: =D11+D12 -> 0 | E13: =E11+E12 -> 0 | F13: =F11+F12 -> 0 | G13: =G11+G12 -> 0 | H13: =H11+H12 -> 0 | I13: =I11+I12 -> 0
A14: Total Income | B14: =B9+B13 -> 565.292 | C14: =C9+C13 -> 1076.1319 | D14: =D9+D13 -> 1160.9325 | E14: =E9+E13 -> 1195.5694 | F14: =F9+F13 -> 1230.684 | G14: =G9+G13 -> 1266.2764 | H14: =H9+H13 -> 1302.3465 | I14: =I9+I13 -> 1338.8944
A16: Cost of Goods Sold: | B16: =B17+B18+B19-B20 -> 393.53944 | C16: =C17+C18+C19-C20 -> 861.66682 | D16: =D17+D18+D19-D20 -> 930.35532 | E16: =E17+E18+E19-E20 -> 958.41119 | F16: =F17+F18+F19-F20 -> 986.85404 | G16: =G17+G18+G19-G20 -> 1015.6839 | H16: =H17+H18+H19-H20 -> 1044.9007 | I16: =I17+I18+I19-I20 -> 1074.5044
A17: Opening Stock | B17: 0 | C17: =B20 -> 70 | D17: =C20 -> 80 | E17: =D20 -> 90 | F17: =E20 -> 100 | G17: =F20 -> 110 | H17: =G20 -> 120 | I17: =H20 -> 130
A18: Add: CIF Value of Imports
A19: Other purchases | B19: =B7*82% -> 463.53944 | C19: =C7*81% -> 871.66682 | D19: =D7*81% -> 940.35532 | E19: =E7*81% -> 968.41119 | F19: =F7*81% -> 996.85404 | G19: =G7*81% -> 1025.6839 | H19: =H7*81% -> 1054.9007 | I19: =I7*81% -> 1084.5044
A20: Less:Closing Stock | B20: 70 | C20: 80 | D20: 90 | E20: 100 | F20: 110 | G20: 120 | H20: 130 | I20: 140
A22: Selling, General & Admin Expenses | B22: =SUM(B23:B28) -> 44 | C22: =SUM(C23:C28) -> 75 | D22: =SUM(D23:D28) -> 80 | E22: =SUM(E23:E28) -> 85 | F22: =SUM(F23:F28) -> 90 | G22: =SUM(G23:G28) -> 95 | H22: =SUM(H23:H28) -> 100 | I22: =SUM(I23:I28) -> 105
A23: Salary / Wages | B23: 24 | C23: 42.5 | D23: 45 | E23: 47.5 | F23: 50 | G23: 52.5 | H23: 55 | I23: 57.5
A24: Selling Expenses
A25: Other admin & general expenses | B25: 20 | C25: 32.5 | D25: 35 | E25: 37.5 | F25: 40 | G25: 42.5 | H25: 45 | I25: 47.5
A26: Baddebts
A27: Rent paid for premises
A28: Remuneration to partners / directors
A30: Interest expenses | B30: =SUM(B31:B34) -> 35.05606 | C30: =SUM(C31:C34) -> 40.423044 | D30: =SUM(D31:D34) -> 35.760151 | E30: =SUM(E31:E34) -> 30.647631 | F30: =SUM(F31:F34) -> 25.055521 | G30: =SUM(G31:G34) -> 18.938832 | H30: =SUM(H31:H34) -> 12.248356 | I30: =SUM(I31:I34) -> 7.3018148
A31: On Term Loan | B31: 28.30606 | C31: 33.673044 | D31: 29.010151 | E31: 23.897631 | F31: 18.305521 | G31: 12.188832 | H31: 5.4983561 | I31: 0.55181481
A32: On CC/OD a/cs | B32: 6.75 | C32: 6.75 | D32: 6.75 | E32: 6.75 | F32: 6.75 | G32: 6.75 | H32: 6.75 | I32: 6.75
A33: Other Interest
A34: Interest on unsecured loans (Considered as Quasi Equity)
A36: Other Non-Cash Expenses
A37: Depreciation / Amortisation | B37: ='Fixed Asset Chart'!E5 -> 81.966027 | C37: ='Fixed Asset Chart'!F5 -> 69.671123 | D37: ='Fixed Asset Chart'!G5 -> 59.220455 | E37: ='Fixed Asset Chart'!H5 -> 50.337386 | F37: ='Fixed Asset Chart'!I5 -> 42.786778 | G37: ='Fixed Asset Chart'!J5 -> 36.368762 | H37: ='Fixed Asset Chart'!K5 -> 30.913447 | I37: ='Fixed Asset Chart'!L5 -> 26.27643
A38: Non-Operating Exp
A39: Profit before tax | B39: =B14-B22-B30-B36-B37-B38-B16 -> 10.730473 | C39: =C14-C22-C30-C36-C37-C38-C16 -> 29.370889 | D39: =D14-D22-D30-D36-D37-D38-D16 -> 55.596569 | E39: =E14-E22-E30-E36-E37-E38-E16 -> 71.173164 | F39: =F14-F22-F30-F36-F37-F38-F16 -> 85.987661 | G39: =G14-G22-G30-G36-G37-G38-G16 -> 100.28492 | H39: =H14-H22-H30-H36-H37-H38-H16 -> 114.28403 | I39: =I14-I22-I30-I36-I37-I38-I16 -> 125.81169
A40: Deferred Tax Liability
A41: Deferred Tax Asset
A42: Tax provision/Tax paid | B42: =B39*30% -> 3.219142 | C42: =C39*30% -> 8.8112667 | D42: =D39*30% -> 16.678971 | E42: =E39*30% -> 21.351949 | F42: =F39*30% -> 25.796298 | G42: =G39*30% -> 30.085475 | H42: =H39*30% -> 34.285209 | I42: =I39*30% -> 37.743506
A43: Profit after tax | B43: =B39-B42 -> 7.5113314 | C43: =C39-C42 -> 20.559622 | D43: =D39-D42 -> 38.917599 | E43: =E39-E42 -> 49.821215 | F43: =F39-F42 -> 60.191363 | G43: =G39-G42 -> 70.199442 | H43: =H39-H42 -> 79.998822 | I43: =I39-I42 -> 88.06818
A45: P&L Ratios
...

Sheet Balance Sheet
A1: BALANCE SHEET
A2: LIABILITIES
A3: DESCRIPTION | B3: 2027 | C3: 2028 | D3: 2029 | E3: 2030 | F3: 2031 | G3: 2032 | H3: 2033 | I3: 2034
B4: Projected | C4: Projected | D4: Projected | E4: Projected | F4: Projected | G4: Projected | H4: Projected | I4: Projected
A6: Total Capital | B6: =SUM(B7:B10) -> 157.51133 | C6: =SUM(C7:C10) -> 178.07095 | D6: =SUM(D7:D10) -> 216.98855 | E6: =SUM(E7:E10) -> 266.80977 | F6: =SUM(F7:F10) -> 327.00113 | G6: =SUM(G7:G10) -> 397.20057 | H6: =SUM(H7:H10) -> 477.19939 | I6: =SUM(I7:I10) -> 565.26757
A7: Capital | B7: =150+'P&L'!B43 -> 157.51133 | C7: =B7+'P&L'!C43 -> 178.07095 | D7: =C7+'P&L'!D43 -> 216.98855 | E7: =D7+'P&L'!E43 -> 266.80977 | F7: =E7+'P&L'!F43 -> 327.00113 | G7: =F7+'P&L'!G43 -> 397.20057 | H7: =G7+'P&L'!H43 -> 477.19939 | I7: =H7+'P&L'!I43 -> 565.26757
A8: Share Premium
A9: Reserves & Surplus
A10: Deferred Tax Liabilities | B10: 0 | C10: 0 | D10: 0 | E10: 0 | F10: 0 | G10: 0 | H10: 0 | I10: 0
A12: Secured Loans | B12: =SUM(B13:B16) -> 470.24739 | C12: =SUM(C13:C16) -> 421.91005 | D12: =SUM(D13:D16) -> 367.40957 | E12: =SUM(E13:E16) -> 307.79658 | F12: =SUM(F13:F16) -> 242.59148 | G12: =SUM(G13:G16) -> 171.26968 | H12: =SUM(H13:H16) -> 93.257415 | I12: =SUM(I13:I16) -> 75
A13: CC/OD | B13: 75 | C13: 75 | D13: 75 | E13: 75 | F13: 75 | G13: 75 | H13: 75 | I13: 75
A14: Long term loans - Term Loan
A15: Installment due in next 1 year | B15: 48.337347 | C15: 54.500473 | D15: 59.612994 | E15: 65.205104 | F15: 71.321792 | G15: 78.012269 | H15: 18.257415 | I15: 0
A16: Installment due in after 1 year | B16: =C15+C16 -> 346.91005 | C16: =D15+D16 -> 292.40957 | D16: =E15+E16 -> 232.79658 | E16: =F15+F16 -> 167.59148 | F16: =G15+G16 -> 96.269684 | G16: =H15+H16 -> 18.257415 | H16: =I15+I16 -> 0 | I16: 0
A18: Unsecured Loans | B18: =SUM(B19:B21) -> 25 | C18: =SUM(C19:C21) -> 25 | D18: =SUM(D19:D21) -> 25 | E18: =SUM(E19:E21) -> 25 | F18: =SUM(F19:F21) -> 25 | G18: =SUM(G19:G21) -> 25 | H18: =SUM(H19:H21) -> 25 | I18: =SUM(I19:I21) -> 25
A19: Quasi Equity | B19: 25 | C19: 25 | D19: 25 | E19: 25 | F19: 25 | G19: 25 | H19: 25 | I19: 25
A20: Other – UNS – Short Term
A21: Other – UNS – Long Term
A23: Current Liabilities | B23: =SUM(B24:B27) -> 74.530916 | C23: =SUM(C24:C27) -> 136.16286 | D23: =SUM(D24:D27) -> 146.86523 | E23: =SUM(E24:E27) -> 151.47116 | F23: =SUM(F24:F27) -> 156.12936 | G23: =SUM(G24:G27) -> 160.83974 | H23: =SUM(H24:H27) -> 165.60216 | I23: =SUM(I24:I27) -> 170.41651
A24: Sundry Creditors | B24: ='P&L'!B19*15% -> 69.530916 | C24: ='P&L'!C19*14.99% -> 130.66286 | D24: ='P&L'!D19*14.98% -> 140.86523 | E24: ='P&L'!E19*14.97% -> 144.97116 | F24: ='P&L'!F19*14.96% -> 149.12936 | G24: ='P&L'!G19*14.95% -> 153.33974 | H24: ='P&L'!H19*14.94% -> 157.60216 | I24: ='P&L'!I19*14.93% -> 161.91651
A25: Provisions for expenses | B25: 5 | C25: 5.5 | D25: 6 | E25: 6.5 | F25: 7 | G25: 7.5 | H25: 8 | I25: 8.5
A26: Advance for raw material (advance for mobilization against BG)
A27: Other Current liabilities
A29: TOTAL LIABILITIES | B29: =B6+B12+B18+B23 -> 727.28964 | C29: =C6+C12+C18+C23 -> 761.14386 | D29: =D6+D12+D18+D23 -> 756.26335 | E29: =E6+E12+E18+E23 -> 751.0775 | F29: =F6+F12+F18+F23 -> 750.72197 | G29: =G6+G12+G18+G23 -> 754.30999 | H29: =H6+H12+H18+H23 -> 761.05897 | I29: =I6+I12+I18+I23 -> 835.68409
A31: ASSETS
A32: DESCRIPTION | B32: 2027 | C32: 2028 | D32: 2029 | E32: 2030 | F32: 2031 | G32: 2032 | H32: 2033 | I32: 2034
B33: Projected | C33: Projected | D33: Projected | E33: Projected | F33: Projected | G33: Projected | H33: Projected | I33: Projected
A35: Fixed Assets (Opening) | B35: 0 | C35: =B38 -> 464.47397 | D35: =C38 -> 394.80285 | E35: =D38 -> 335.5824 | F35: =E38 -> 285.24501 | G35: =F38 -> 242.45823 | H35: =G38 -> 206.08947 | I35: =H38 -> 175.17602
A36: Addition to Fixed Assets (net of sales) | B36: 546.44
A37: Less : Depreciation | B37: ='P&L'!B37 -> 81.966027 | C37: ='P&L'!C37 -> 69.671123 | D37: ='P&L'!D37 -> 59.220455 | E37: ='P&L'!E37 -> 50.337386 | F37: ='P&L'!F37 -> 42.786778 | G37: ='P&L'!G37 -> 36.368762 | H37: ='P&L'!H37 -> 30.913447 | I37: ='P&L'!I37 -> 26.27643
A38: Net Fixed Assets | B38: =B35+B36-B37 -> 464.47397 | C38: =C35+C36-C37 -> 394.80285 | D38: =D35+D36-D37 -> 335.5824 | E38: =E35+E36-E37 -> 285.24501 | F38: =F35+F36-F37 -> 242.45823 | G38: =G35+G36-G37 -> 206.08947 | H38: =H35+H36-H37 -> 175.17602 | I38: =I35+I36-I37 -> 148.89959
A40: Investments | B40: =SUM(B41:B43) -> 0 | C40: =SUM(C41:C43) -> 0 | D40: =SUM(D41:D43) -> 0 | E40: =SUM(E41:E43) -> 0 | F40: =SUM(F41:F43) -> 0 | G40: =SUM(G41:G43) -> 0 | H40: =SUM(H41:H43) -> 0 | I40: =SUM(I41:I43) -> 0
A41: In Group concerns
A42: Long Term | B42: 0 | C42: 0 | D42: 0 | E42: 0 | F42: 0 | G42: 0 | H42: 0 | I42: 0
A43: Short Term
A45: Current Assets | B45: =SUM(B46:B56) -> 247.8176 | C45: =SUM(C46:C56) -> 346.34165 | D45: =SUM(D46:D56) -> 395.67771 | E45: =SUM(E46:E56) -> 435.82754 | F45: =SUM(F46:F56) -> 473.26495 | G45: =SUM(G46:G56) -> 508.21982 | H45: =SUM(H46:H56) -> 540.88199 | I45: =SUM(I46:I56) -> 586.78131
A46: Cash & Bank Balances | B46: 5 | C46: 5.5 | D46: 6 | E46: 6.5 | F46: 7 | G46: 7.5 | H46: 8 | I46: 8.5
A47: Margin Money
A48: Inventories | B48: ='P&L'!B20 -> 70 | C48: ='P&L'!C20 -> 80 | D48: ='P&L'!D20 -> 90 | E48: ='P&L'!E20 -> 100 | F48: ='P&L'!F20 -> 110 | G48: ='P&L'!G20 -> 120 | H48: ='P&L'!H20 -> 130 | I48: ='P&L'!I20 -> 140
A49: Sundry Debtors
...

Sheet Production Chart
A1: Proposed Production And Sales Calculation - Phase 1 - 23 Waterjet Machines
A2: Particulars | B2: FY 2026-27 | C2: FY 2027-28 | D2: FY 2028-29 | E2: FY 2029-30 | F2: FY 2030-31 | G2: FY 2031-32 | H2: FY 2032-33 | I2: FY 2033-34
A3: No of Machines | B3: 23 | C3: 23 | D3: 23 | E3: 23 | F3: 23 | G3: 23 | H3: 23 | I3: 23
A4: Proposed Production per day per Machine | B4: 350 | C4: 350 | D4: 350 | E4: 350 | F4: 350 | G4: 350 | H4: 350 | I4: 350
A5: Annual Production (350 days) | B5: =B4*275*B3 -> 2213750 | C5: =C4*350*C3 -> 2817500 | D5: =D4*350*D3 -> 2817500 | E5: =E4*350*E3 -> 2817500 | F5: =F4*350*F3 -> 2817500 | G5: =G4*350*G3 -> 2817500 | H5: =H4*350*H3 -> 2817500 | I5: =I4*350*I3 -> 2817500
A6: Proposed Capacity Utilisation | B6: 0.8 | C6: 0.85 | D6: 0.9 | E6: 0.91 | F6: 0.92 | G6: 0.93 | H6: 0.94 | I6: 0.95
A7: Selling Price per mtr | B7: 26 | C7: 26.5 | D7: 27 | E7: 27.5 | F7: 28 | G7: 28.5 | H7: 29 | I7: 29.5
A8: Proposed Annual Sales in Lakhs | B8: =B5*B6*B7/10^5 -> 460.46 | C8: =C5*C6*C7/10^5 -> 634.64188 | D8: =D5*D6*D7/10^5 -> 684.6525 | E8: =E5*E6*E7/10^5 -> 705.07938 | F8: =F5*F6*F7/10^5 -> 725.788 | G8: =G5*G6*G7/10^5 -> 746.77837 | H8: =H5*H6*H7/10^5 -> 768.0505 | I8: =I5*I6*I7/10^5 -> 789.60438
A10: Note | B10: Commercial Production Start date considered from 01-06-2026
B11: Hence, 275 days Production Considered for FY 2026-27
A13: Proposed Production And Sales Calculation - Phase 2 - 16 Waterjet Machines
A14: Particulars | B14: FY 2026-27 | C14: FY 2027-28 | D14: FY 2028-29 | E14: FY 2029-30 | F14: FY 2030-31 | G14: FY 2031-32 | H14: FY 2032-33 | I14: FY 2033-34
A15: No of Machines | B15: 16 | C15: 16 | D15: 16 | E15: 16 | F15: 16 | G15: 16 | H15: 16 | I15: 16
A16: Proposed Production per day per Machine | B16: 350 | C16: 350 | D16: 350 | E16: 350 | F16: 350 | G16: 350 | H16: 350 | I16: 350
A17: Annual Production (350 days) | B17: =B16*90*B15 -> 504000 | C17: =C16*350*C15 -> 1960000 | D17: =D16*350*D15 -> 1960000 | E17: =E16*350*E15 -> 1960000 | F17: =F16*350*F15 -> 1960000 | G17: =G16*350*G15 -> 1960000 | H17: =H16*350*H15 -> 1960000 | I17: =I16*350*I15 -> 1960000
A18: Proposed Capacity Utilisation | B18: 0.8 | C18: 0.85 | D18: 0.9 | E18: 0.91 | F18: 0.92 | G18: 0.93 | H18: 0.94 | I18: 0.95
A19: Selling Price per mtr | B19: 26 | C19: 26.5 | D19: 27 | E19: 27.5 | F19: 28 | G19: 28.5 | H19: 29 | I19: 29.5
A20: Proposed Annual Sales in Lakhs | B20: =B17*B18*B19/10^5 -> 104.832 | C20: =C17*C18*C19/10^5 -> 441.49 | D20: =D17*D18*D19/10^5 -> 476.28 | E20: =E17*E18*E19/10^5 -> 490.49 | F20: =F17*F18*F19/10^5 -> 504.896 | G20: =G17*G18*G19/10^5 -> 519.498 | H20: =H17*H18*H19/10^5 -> 534.296 | I20: =I17*I18*I19/10^5 -> 549.29
A22: Note | B22: Commercial Production Start date considered from 01-01-2027
B23: Hence, 90 days Production Considered for FY 2026-27
A25: Proposed Total Annual Sales in Lakhs | B25: =B20+B8 -> 565.292 | C25: =C20+C8 -> 1076.1319 | D25: =D20+D8 -> 1160.9325 | E25: =E20+E8 -> 1195.5694 | F25: =F20+F8 -> 1230.684 | G25: =G20+G8 -> 1266.2764 | H25: =H20+H8 -> 1302.3465 | I25: =I20+I8 -> 1338.8944

Sheet Fixed Asset Chart
A1: Depreciation Chart Year Wise
B2: Amount in Lakhs | C2: Rate | D2: FY 2025-26 | E2: FY 2026-27 | F2: FY 2027-28 | G2: FY 2028-29 | H2: FY 2029-30 | I2: FY 2030-31 | J2: FY 2031-32 | K2: FY 2032-33 | L2: FY 2033-34
A3: Proposed Machinery - Phase 1 | B3: ='Machinery Chart'!F11/10^5 -> 335.4549 | C3: 0.15 | D3: 0 | E3: =B3*C3 -> 50.318235 | F3: =E3*0.85 -> 42.7705 | G3: =F3*0.85 -> 36.354925 | H3: =G3*0.85 -> 30.901686 | I3: =H3*0.85 -> 26.266433 | J3: =I3*0.85 -> 22.326468 | K3: =J3*0.85 -> 18.977498 | L3: =K3*0.85 -> 16.130873
A4: Proposed Machinery - Phase 2 | B4: ='Machinery Chart'!F21/10^5 -> 210.98528 | C4: 0.15 | D4: 0 | E4: =B4*C4 -> 31.647792 | F4: =E4*0.85 -> 26.900623 | G4: =F4*0.85 -> 22.86553 | H4: =G4*0.85 -> 19.4357 | I4: =H4*0.85 -> 16.520345 | J4: =I4*0.85 -> 14.042293 | K4: =J4*0.85 -> 11.935949 | L4: =K4*0.85 -> 10.145557
A5: Total Depreciation | D5: =SUM(D3:D4) -> 0 | E5: =SUM(E3:E4) -> 81.966027 | F5: =SUM(F3:F4) -> 69.671123 | G5: =SUM(G3:G4) -> 59.220455 | H5: =SUM(H3:H4) -> 50.337386 | I5: =SUM(I3:I4) -> 42.786778 | J5: =SUM(J3:J4) -> 36.368762 | K5: =SUM(K3:K4) -> 30.913447 | L5: =SUM(L3:L4) -> 26.27643
A6: Note - 1 | B6: Phase 1 Machinery is planned to be installed in May, 2026
A7: Note - 2 | B7: Phase 2 Machinery is planned to be installed in December, 2026

Sheet Repayment Schedule - TL 1
A1: TL 1 Ammortization Schedule | I1: Note | J1: Machinery Disbursement is planned in April, 2026.
A2: Loan Details | J2: So EMI starts from April, 2026
A3: Amount | B3: Rs 251.59 Lakhs
A4: Tenure | B4: 7 Years (including Moratorium of 6 Months)
A5: ROI | B5: 0.09
I6: Summary of Term Loan
A7: No | B7: Opening Balance | C7: Principal | D7: Interest | E7: EMI | F7: Closing Balance | J7: Principal | K7: Interest | L7: Total | M7: Total in Lakhs
A8: 1 | B8: 25159000 | C8: 0 | D8: =B8*9%/12 -> 188692.5 | E8: =D8 -> 188692.5 | F8: =B8-C8 -> 25159000 | I8: FY 2025-26 | J8: 0 | K8: 0 | L8: =SUM(J8:K8) -> 0 | M8: =L8/10^5 -> 0
A9: 2 | B9: =F8 -> 25159000 | C9: 0 | D9: =B9*9%/12 -> 188692.5 | E9: =D9 -> 188692.5 | F9: =B9-C9 -> 25159000 | I9: FY 2026-27 | J9: =SUM(C8:C19) -> 1458260.4 | K9: =SUM(D8:D19) -> 2237206 | L9: =SUM(J9:K9) -> 3695466.4 | M9: =L9/10^5 -> 36.954664
A10: 3 | B10: =F9 -> 25159000 | C10: 0 | D10: =B10*9%/12 -> 188692.5 | E10: =D10 -> 188692.5 | F10: =B10-C10 -> 25159000 | I10: FY 2027-28 | J10: =SUM(C20:C31) -> 3120180.2 | K10: =SUM(D20:D31) -> 2006442.5 | L10: =SUM(J10:K10) -> 5126622.7 | M10: =L10/10^5 -> 51.266227
A11: 4 | B11: =F10 -> 25159000 | C11: 0 | D11: =B11*9%/12 -> 188692.5 | E11: =D11 -> 188692.5 | F11: =B11-C11 -> 25159000 | I11: FY 2028-29 | J11: =SUM(C32:C43) -> 3412874.6 | K11: =SUM(D32:D43) -> 1713748.1 | L11: =SUM(J11:K11) -> 5126622.7 | M11: =L11/10^5 -> 51.266227
A12: 5 | B12: =F11 -> 25159000 | C12: 0 | D12: =B12*9%/12 -> 188692.5 | E12: =D12 -> 188692.5 | F12: =B12-C12 -> 25159000 | I12: FY 2029-30 | J12: =SUM(C44:C55) -> 3733025.8 | K12: =SUM(D44:D55) -> 1393596.9 | L12: =SUM(J12:K12) -> 5126622.7 | M12: =L12/10^5 -> 51.266227
A13: 6 | B13: =F12 -> 25159000 | C13: 0 | D13: =B13*9%/12 -> 188692.5 | E13: =D13 -> 188692.5 | F13: =B13-C13 -> 25159000 | I13: FY 2030-31 | J13: =SUM(C56:C67) -> 4083209.3 | K13: =SUM(D56:D67) -> 1043413.4 | L13: =SUM(J13:K13) -> 5126622.7 | M13: =L13/10^5 -> 51.266227
A14: 7 | B14: =F13 -> 25159000 | C14: =E14-D14 -> 238526.06 | D14: =B14*9%/12 -> 188692.5 | E14: 427218.56 | F14: =B14-C14 -> 24920474 | I14: FY 2030-32 | J14: =SUM(C68:C79) -> 4466242.5 | K14: =SUM(D68:D79) -> 660380.17 | L14: =SUM(J14:K14) -> 5126622.7 | M14: =L14/10^5 -> 51.266227
A15: 8 | B15: =F14 -> 24920474 | C15: =E15-D15 -> 240315.01 | D15: =B15*9%/12 -> 186903.55 | E15: 427218.56 | F15: =B15-C15 -> 24680159 | I15: FY 2032-33 | J15: =SUM(C80:C91) -> 4885206.9 | K15: =SUM(D80:D91) -> 241415.82 | L15: =SUM(J15:K15) -> 5126622.7 | M15: =L15/10^5 -> 51.266227
A16: 9 | B16: =F15 -> 24680159 | C16: =E16-D16 -> 242117.37 | D16: =B16*9%/12 -> 185101.19 | E16: 427218.56 | F16: =B16-C16 -> 24438042 | I16: FY 2033-34 | J16: 0 | K16: 0 | L16: 0 | M16: =L16/10^5 -> 0
A17: 10 | B17: =F16 -> 24438042 | C17: =E17-D17 -> 243933.25 | D17: =B17*9%/12 -> 183285.31 | E17: 427218.56 | F17: =B17-C17 -> 24194108 | I17: Total | J17: =SUM(J8:J16) -> 25159000 | K17: =SUM(K8:K16) -> 9296202.9 | L17: =SUM(L8:L16) -> 34455203 | M17: =SUM(M8:M16) -> 344.55203
A18: 11 | B18: =F17 -> 24194108 | C18: =E18-D18 -> 245762.75 | D18: =B18*9%/12 -> 181455.81 | E18: 427218.56 | F18: =B18-C18 -> 23948346
A19: 12 | B19: =F18 -> 23948346 | C19: =E19-D19 -> 247605.97 | D19: =B19*9%/12 -> 179612.59 | E19: 427218.56 | F19: =B19-C19 -> 23700740
A20: 13 | B20: =F19 -> 23700740 | C20: =E20-D20 -> 249463.01 | D20: =B20*9%/12 -> 177755.55 | E20: 427218.56 | F20: =B20-C20 -> 23451277
A21: 14 | B21: =F20 -> 23451277 | C21: =E21-D21 -> 251333.99 | D21: =B21*9%/12 -> 175884.57 | E21: 427218.56 | F21: =B21-C21 -> 23199943
A22: 15 | B22: =F21 -> 23199943 | C22: =E22-D22 -> 253218.99 | D22: =B22*9%/12 -> 173999.57 | E22: 427218.56 | F22: =B22-C22 -> 22946724
A23: 16 | B23: =F22 -> 22946724 | C23: =E23-D23 -> 255118.13 | D23: =B23*9%/12 -> 172100.43 | E23: 427218.56 | F23: =B23-C23 -> 22691605
A24: 17 | B24: =F23 -> 22691605 | C24: =E24-D24 -> 257031.52 | D24: =B24*9%/12 -> 170187.04 | E24: 427218.56 | F24: =B24-C24 -> 22434574
A25: 18 | B25: =F24 -> 22434574 | C25: =E25-D25 -> 258959.26 | D25: =B25*9%/12 -> 168259.3 | E25: 427218.56 | F25: =B25-C25 -> 22175615
A26: 19 | B26: =F25 -> 22175615 | C26: =E26-D26 -> 260901.45 | D26: =B26*9%/12 -> 166317.11 | E26: 427218.56 | F26: =B26-C26 -> 21914713
A27: 20 | B27: =F26 -> 21914713 | C27: =E27-D27 -> 262858.21 | D27: =B27*9%/12 -> 164360.35 | E27: 427218.56 | F27: =B27-C27 -> 21651855
A28: 21 | B28: =F27 -> 21651855 | C28: =E28-D28 -> 264829.65 | D28: =B28*9%/12 -> 162388.91 | E28: 427218.56 | F28: =B28-C28 -> 21387025
A29: 22 | B29: =F28 -> 21387025 | C29: =E29-D29 -> 266815.87 | D29: =B29*9%/12 -> 160402.69 | E29: 427218.56 | F29: =B29-C29 -> 21120210
... A90: 83 | B90: =F89 -> 844920.18 | C90: =E90-D90 -> 420881.66 | D90: =B90*9%/12 -> 6336.9013 | E90: 427218.56 | F90: =B90-C90 -> 424038.52
A91: 84 | B91: =F90 -> 424038.52 | C91: =E91-D91 -> 424038.3 | D91: =B91*9%/12 -> 3180.2889 | E91: =427218.56+0.025 -> 427218.59 | F91: =B91-C91 -> 0.22391468
B92: Total | C92: =SUM(C8:C91) -> 25159000 | D92: =SUM(D8:D91) -> 9296202.9

Sheet Repayment Schedule - TL 2
A1: TL 1 Ammortization Schedule | I1: Note | J1: Machinery Disbursement is planned in November, 2026.
A2: Loan Details | J2: So EMI starts from November, 2026
A3: Amount | B3: Rs 158.24 Lakhs
A4: Tenure | B4: 7 Years (including Moratorium of 6 Months)
A5: ROI | B5: 0.09
I6: Summary of Term Loan
A7: No | B7: Opening Balance | C7: Principal | D7: Interest | E7: EMI | F7: Closing Balance | J7: Principal | K7: Interest | L7: Total | M7: Total in Lakhs
A8: 1 | B8: 15824000 | C8: 0 | D8: =B8*9%/12 -> 118680 | E8: =D8 -> 118680 | F8: =B8-C8 -> 15824000 | I8: FY 2025-26 | J8: 0 | K8: 0 | L8: 0 | M8: =L8/10^5 -> 0
A9: 2 | B9: =F8 -> 15824000 | C9: 0 | D9: =B9*9%/12 -> 118680 | E9: =D9 -> 118680 | F9: =B9-C9 -> 15824000 | I9: FY 2026-27 | J9: =SUM(C8:C12) -> 0 | K9: =SUM(D8:D12) -> 593400 | L9: =SUM(J9:K9) -> 593400 | M9: =L9/10^5 -> 5.934
A10: 3 | B10: =F9 -> 15824000 | C10: 0 | D10: =B10*9%/12 -> 118680 | E10: =D10 -> 118680 | F10: =B10-C10 -> 15824000 | I10: FY 2027-28 | J10: =SUM(C13:C24) -> 1713554.5 | K10: =SUM(D13:D24) -> 1360861.9 | L10: =SUM(J10:K10) -> 3074416.4 | M10: =L10/10^5 -> 30.744164
A11: 4 | B11: =F10 -> 15824000 | C11: 0 | D11: =B11*9%/12 -> 118680 | E11: =D11 -> 118680 | F11: =B11-C11 -> 15824000 | I11: FY 2028-29 | J11: =SUM(C25:C36) -> 2037172.7 | K11: =SUM(D25:D36) -> 1187267 | L11: =SUM(J11:K11) -> 3224439.7 | M11: =L11/10^5 -> 32.244397
A12: 5 | B12: =F11 -> 15824000 | C12: 0 | D12: =B12*9%/12 -> 118680 | E12: =D12 -> 118680 | F12: =B12-C12 -> 15824000 | I12: FY 2029-30 | J12: =SUM(C37:C48) -> 2228273.6 | K12: =SUM(D37:D48) -> 996166.12 | L12: =SUM(J12:K12) -> 3224439.7 | M12: =L12/10^5 -> 32.244397
A13: 6 | B13: =F12 -> 15824000 | C13: 0 | D13: =B13*9%/12 -> 118680 | E13: =D13 -> 118680 | F13: =B13-C13 -> 15824000 | I13: FY 2030-31 | J13: =SUM(C49:C60) -> 2437301 | K13: =SUM(D49:D60) -> 787138.69 | L13: =SUM(J13:K13) -> 3224439.7 | M13: =L13/10^5 -> 32.244397
A14: 7 | B14: =F13 -> 15824000 | C14: =E14-D14 -> 150023.31 | D14: =B14*9%/12 -> 118680 | E14: 268703.31 | F14: =B14-C14 -> 15673977 | I14: FY 2030-32 | J14: =SUM(C61:C72) -> 2665936.7 | K14: =SUM(D61:D72) -> 558503.04 | L14: =SUM(J14:K14) -> 3224439.7 | M14: =L14/10^5 -> 32.244397
A15: 8 | B15: =F14 -> 15673977 | C15: =E15-D15 -> 151148.48 | D15: =B15*9%/12 -> 117554.83 | E15: 268703.31 | F15: =B15-C15 -> 15522828 | I15: FY 2032-33 | J15: =SUM(C73:C84) -> 2916019.9 | K15: =SUM(D73:D84) -> 308419.79 | L15: =SUM(J15:K15) -> 3224439.7 | M15: =L15/10^5 -> 32.244397
A16: 9 | B16: =F15 -> 15522828 | C16: =E16-D16 -> 152282.1 | D16: =B16*9%/12 -> 116421.21 | E16: 268703.31 | F16: =B16-C16 -> 15370546 | I16: FY 2033-34 | J16: =SUM(C85:C91) -> 1825741.5 | K16: =SUM(D85:D91) -> 55181.481 | L16: =SUM(J16:K16) -> 1880923 | M16: =L16/10^5 -> 18.80923
A17: 10 | B17: =F16 -> 15370546 | C17: =E17-D17 -> 153424.21 | D17: =B17*9%/12 -> 115279.1 | E17: 268703.31 | F17: =B17-C17 -> 15217122 | I17: Total | J17: =SUM(J8:J16) -> 15824000 | K17: =SUM(K8:K16) -> 5846938 | L17: =SUM(L8:L16) -> 21670938 | M17: =SUM(M8:M16) -> 216.70938
A18: 11 | B18: =F17 -> 15217122 | C18: =E18-D18 -> 154574.9 | D18: =B18*9%/12 -> 114128.41 | E18: 268703.31 | F18: =B18-C18 -> 15062547
A19: 12 | B19: =F18 -> 15062547 | C19: =E19-D19 -> 155734.21 | D19: =B19*9%/12 -> 112969.1 | E19: 268703.31 | F19: =B19-C19 -> 14906813
A20: 13 | B20: =F19 -> 14906813 | C20: =E20-D20 -> 156902.21 | D20: =B20*9%/12 -> 111801.1 | E20: 268703.31 | F20: =B20-C20 -> 14749911
A21: 14 | B21: =F20 -> 14749911 | C21: =E21-D21 -> 158078.98 | D21: =B21*9%/12 -> 110624.33 | E21: 268703.31 | F21: =B21-C21 -> 14591832
A22: 15 | B22: =F21 -> 14591832 | C22: =E22-D22 -> 159264.57 | D22: =B22*9%/12 -> 109438.74 | E22: 268703.31 | F22: =B22-C22 -> 14432567
A23: 16 | B23: =F22 -> 14432567 | C23: =E23-D23 -> 160459.06 | D23: =B23*9%/12 -> 108244.25 | E23: 268703.31 | F23: =B23-C23 -> 14272108
A24: 17 | B24: =F23 -> 14272108 | C24: =E24-D24 -> 161662.5 | D24: =B24*9%/12 -> 107040.81 | E24: 268703.31 | F24: =B24-C24 -> 14110445
A25: 18 | B25: =F24 -> 14110445 | C25: =E25-D25 -> 162874.97 | D25: =B25*9%/12 -> 105828.34 | E25: 268703.31 | F25: =B25-C25 -> 13947570
A26: 19 | B26: =F25 -> 13947570 | C26: =E26-D26 -> 164096.53 | D26: =B26*9%/12 -> 104606.78 | E26: 268703.31 | F26: =B26-C26 -> 13783474
A27: 20 | B27: =F26 -> 13783474 | C27: =E27-D27 -> 165327.26 | D27: =B27*9%/12 -> 103376.05 | E27: 268703.31 | F27: =B27-C27 -> 13618147
A28: 21 | B28: =F27 -> 13618147 | C28: =E28-D28 -> 166567.21 | D28: =B28*9%/12 -> 102136.1 | E28: 268703.31 | F28: =B28-C28 -> 13451579
A29: 22 | B29: =F28 -> 13451579 | C29: =E29-D29 -> 167816.46 | D29: =B29*9%/12 -> 100886.85 | E29: 268703.31 | F29: =B29-C29 -> 13283763
... A91: 84 | B91: =F90 -> 266702.85 | C91: =E91-D91 -> 266702.85 | D91: =B91*9%/12 -> 2000.2714 | E91: 268703.12 | F91: =B91-C91 -> -0.00078418152
B92: Total | C92: =SUM(C8:C91) -> 15824000 | D92: =SUM(D8:D91) -> 5846938

Sheet Summary of TL Repayment
A1: Summary of Total Term Loan Repayment
B2: Principal | F2: Interest
B3: Phase 1 | C3: Phase 2 | D3: Total | E3: Total in Lakhs | F3: Phase 1 | G3: Phase 2 | H3: Total | I3: Total in Lakhs
A4: FY 2025-26 | B4: 0 | C4: 0 | D4: =SUM(B4:C4) -> 0 | E4: =D4/10^6 -> 0 | F4: 0 | G4: 0 | H4: =SUM(F4:G4) -> 0 | I4: =H4/10^5 -> 0
A5: FY 2026-27 | B5: 1458260.4 | C5: 0 | D5: =SUM(B5:C5) -> 1458260.4 | E5: =D5/10^5 -> 14.582604 | F5: 2237206 | G5: 593400 | H5: =SUM(F5:G5) -> 2830606 | I5: =H5/10^5 -> 28.30606
A6: FY 2027-28 | B6: 3120180.2 | C6: 1713554.5 | D6: =SUM(B6:C6) -> 4833734.7 | E6: =D6/10^5 -> 48.337347 | F6: 2006442.5 | G6: 1360861.9 | H6: =SUM(F6:G6) -> 3367304.4 | I6: =H6/10^5 -> 33.673044
A7: FY 2028-29 | B7: 3412874.6 | C7: 2037172.7 | D7: =SUM(B7:C7) -> 5450047.3 | E7: =D7/10^5 -> 54.500473 | F7: 1713748.1 | G7: 1187267 | H7: =SUM(F7:G7) -> 2901015.1 | I7: =H7/10^5 -> 29.010151
A8: FY 2029-30 | B8: 3733025.8 | C8: 2228273.6 | D8: =SUM(B8:C8) -> 5961299.4 | E8: =D8/10^5 -> 59.612994 | F8: 1393596.9 | G8: 996166.12 | H8: =SUM(F8:G8) -> 2389763.1 | I8: =H8/10^5 -> 23.897631
A9: FY 2030-31 | B9: 4083209.3 | C9: 2437301 | D9: =SUM(B9:C9) -> 6520510.4 | E9: =D9/10^5 -> 65.205104 | F9: 1043413.4 | G9: 787138.69 | H9: =SUM(F9:G9) -> 1830552.1 | I9: =H9/10^5 -> 18.305521
A10: FY 2030-32 | B10: 4466242.5 | C10: 2665936.7 | D10: =SUM(B10:C10) -> 7132179.2 | E10: =D10/10^5 -> 71.321792 | F10: 660380.17 | G10: 558503.04 | H10: =SUM(F10:G10) -> 1218883.2 | I10: =H10/10^5 -> 12.188832
A11: FY 2032-33 | B11: 4885206.9 | C11: 2916019.9 | D11: =SUM(B11:C11) -> 7801226.9 | E11: =D11/10^5 -> 78.012269 | F11: 241415.82 | G11: 308419.79 | H11: =SUM(F11:G11) -> 549835.61 | I11: =H11/10^5 -> 5.4983561
A12: FY 2033-34 | B12: 0 | C12: 1825741.5 | D12: =SUM(B12:C12) -> 1825741.5 | E12: =D12/10^5 -> 18.257415 | F12: 0 | G12: 55181.481 | H12: =SUM(F12:G12) -> 55181.481 | I12: =H12/10^5 -> 0.55181481
A13: Total | B13: =SUM(B4:B12) -> 25159000 | C13: =SUM(C4:C12) -> 15824000 | D13: =SUM(D4:D12) -> 40983000 | E13: =SUM(E4:E12) -> 409.83 | F13: =SUM(F4:F12) -> 9296202.9 | G13: =SUM(G4:G12) -> 5846938 | H13: =SUM(H4:H12) -> 15143141 | I13: =SUM(I4:I12) -> 151.43141
